Workbook

Sheet Finance_Data
A1: Campaign_ID | B1: Region | C1: Country | D1: Product | E1: Channel | F1: Currency | G1: Start_Date | H1: End_Date | I1: LC_Spend | J1: FX_Rate | K1: USD_Spend | L1: Impressions | M1: Clicks | N1: Sales | O1: Year | P1: Month | Q1: Quarter | R1: Format | S1: Duration | T1: Composite Key
A2: CMP_059 | B2: East | C2: India | D2: Perfume | E2: Retail | F2: SGD | G2: 44927 | H2: 44953 | I2: 45976.91 | J2: 0.2497 | K2: 11480.43 | L2: 146828 | M2: 22431 | N2: 180649.72 | O2: 2023 | P2: January | Q2: Q1 | R2: India | XYZ | PQR | TEST | S2: =H2-G2+1 -> 27 | T2: =_xlfn.TEXTJOIN("_",TRUE,Finance_Data!A2,Finance_Data!B2,Finance_Data!C2,Finance_Data!D2,Finance_Data!E2,Finance_Data!G2,Finance_Data!H2) -> CMP_059_East_India_Perfume_Retail_44927_44953
A3: CMP_001 | B3: North | C3: UK | D3: Skincare | E3: Wholesale | F3: AUD | G3: 44928 | H3: 44985 | I3: 23767.95 | J3: 0.997 | K3: 23696.65 | L3: 313300 | M3: 42898 | N3: 243160.04 | O3: 2023 | P3: January | Q3: Q1 | R3: UK | JKL | MNO | PQR | S3: =H3-G3+1 -> 58 | T3: =_xlfn.TEXTJOIN("_",TRUE,Finance_Data!A3,Finance_Data!B3,Finance_Data!C3,Finance_Data!D3,Finance_Data!E3,Finance_Data!G3,Finance_Data!H3) -> CMP_001_North_UK_Skincare_Wholesale_44928_44985
A4: CMP_027 | B4: East | C4: India | D4: Watch | E4: Wholesale | F4: GBP | G4: 44929 | H4: 44961 | I4: 32407.35 | J4: 1.1323 | K4: 36694.84 | L4: 64382 | M4: 21268 | N4: 110974.3 | O4: 2023 | P4: January | Q4: Q1 | R4: UK | JKL | MNO | PQR | S4: =H4-G4+1 -> 33 | T4: =_xlfn.TEXTJOIN("_",TRUE,Finance_Data!A4,Finance_Data!B4,Finance_Data!C4,Finance_Data!D4,Finance_Data!E4,Finance_Data!G4,Finance_Data!H4) -> CMP_027_East_India_Watch_Wholesale_44929_44961
A5: CMP_027 | B5: East | C5: Singapore | D5: Foundation | E5: Wholesale | F5: SGD | G5: 44930 | H5: 44962 | I5: 4295.8 | J5: 0.6737 | K5: 2894.08 | L5: 228677 | M5: 46629 | N5: 48638.18 | O5: 2023 | P5: January | Q5: Q1 | R5: India | XYZ | PQR | TEST | S5: =H5-G5+1 -> 33 | T5: =_xlfn.TEXTJOIN("_",TRUE,Finance_Data!A5,Finance_Data!B5,Finance_Data!C5,Finance_Data!D5,Finance_Data!E5,Finance_Data!G5,Finance_Data!H5) -> CMP_027_East_Singapore_Foundation_Wholesale_44930_44962
A6: CMP_009 | B6: West | C6: UK | D6: Watch | E6: Ecommerce | F6: USD | G6: 44932 | H6: 44959 | I6: 44295.24 | J6: 0.854 | K6: 37828.13 | L6: 126041 | M6: 12523 | N6: 74800.44 | O6: 2023 | P6: January | Q6: Q1 | R6: India | XYZ | PQR | TEST | S6: =H6-G6+1 -> 28 | T6: =_xlfn.TEXTJOIN("_",TRUE,Finance_Data!A6,Finance_Data!B6,Finance_Data!C6,Finance_Data!D6,Finance_Data!E6,Finance_Data!G6,Finance_Data!H6) -> CMP_009_West_UK_Watch_Ecommerce_44932_44959
A7: CMP_047 | B7: South | C7: UK | D7: Skincare | E7: Retail | F7: USD | G7: 44933 | H7: 44977 | I7: 23557.34 | J7: 0.365 | K7: 8598.43 | L7: 122369 | M7: 437 | N7: 90681.82 | O7: 2023 | P7: January | Q7: Q1 | R7: UK | JKL | MNO | PQR | S7: =H7-G7+1 -> 45 | T7: =_xlfn.TEXTJOIN("_",TRUE,Finance_Data!A7,Finance_Data!B7,Finance_Data!C7,Finance_Data!D7,Finance_Data!E7,Finance_Data!G7,Finance_Data!H7) -> CMP_047_South_UK_Skincare_Retail_44933_44977
A8: CMP_054 | B8: West | C8: Australia | D8: Perfume | E8: Ecommerce | F8: USD | G8: 44934 | H8: 44962 | I8: 39327.61 | J8: 0.614 | K8: 24147.15 | L8: 290608 | M8: 43267 | N8: 69802.27 | O8: 2023 | P8: January | Q8: Q1 | R8: Australia | ABC | BCD | S8: =H8-G8+1 -> 29 | T8: =_xlfn.TEXTJOIN("_",TRUE,Finance_Data!A8,Finance_Data!B8,Finance_Data!C8,Finance_Data!D8,Finance_Data!E8,Finance_Data!G8,Finance_Data!H8) -> CMP_054_West_Australia_Perfume_Ecommerce_44934_44962
A9: CMP_040 | B9: East | C9: India | D9: Skincare | E9: Ecommerce | F9: INR | G9: 44936 | H9: 44995 | I9: 7781.33 | J9: 0.7802 | K9: 6070.99 | L9: 354625 | M9: 23530 | N9: 224159.27 | O9: 2023 | P9: January | Q9: Q1 | R9: Australia | ABC | BCD | S9: =H9-G9+1 -> 60 | T9: =_xlfn.TEXTJOIN("_",TRUE,Finance_Data!A9,Finance_Data!B9,Finance_Data!C9,Finance_Data!D9,Finance_Data!E9,Finance_Data!G9,Finance_Data!H9) -> CMP_040_East_India_Skincare_Ecommerce_44936_44995
A10: CMP_006 | B10: East | C10: Australia | D10: Lipstick | E10: Ecommerce | F10: AUD | G10: 44936 | H10: 44955 | I10: 37414.08 | J10: 0.9125 | K10: 34140.35 | L10: 723612 | M10: 46577 | N10: 92666.15 | O10: 2023 | P10: January | Q10: Q1 | R10: Australia | ABC | BCD | S10: =H10-G10+1 -> 20 | T10: =_xlfn.TEXTJOIN("_",TRUE,Finance_Data!A10,Finance_Data!B10,Finance_Data!C10,Finance_Data!D10,Finance_Data!E10,Finance_Data!G10,Finance_Data!H10) -> CMP_006_East_Australia_Lipstick_Ecommerce_44936_44955
A11: CMP_003 | B11: North | C11: Australia | D11: Luxury Bag | E11: Retail | F11: GBP | G11: 44936 | H11: 44944 | I11: 14037.96 | J11: 1.1467 | K11: 16097.33 | L11: 707640 | M11: 38271 | N11: 198355.76 | O11: 2023 | P11: January | Q11: Q1 | R11: USA | DEF | GHI | S11: =H11-G11+1 -> 9 | T11: =_xlfn.TEXTJOIN("_",TRUE,Finance_Data!A11,Finance_Data!B11,Finance_Data!C11,Finance_Data!D11,Finance_Data!E11,Finance_Data!G11,Finance_Data!H11) -> CMP_003_North_Australia_Luxury Bag_Retail_44936_44944
A12: CMP_009 | B12: East | C12: UK | D12: Foundation | E12: Wholesale | F12: AUD | G12: 44939 | H12: 44980 | I12: 41722.33 | J12: 0.5056 | K12: 21094.81 | L12: 812598 | M12: 12055 | N12: 120092.36 | O12: 2023 | P12: January | Q12: Q1 | R12: UK | JKL | MNO | PQR | S12: =H12-G12+1 -> 42 | T12: =_xlfn.TEXTJOIN("_",TRUE,Finance_Data!A12,Finance_Data!B12,Finance_Data!C12,Finance_Data!D12,Finance_Data!E12,Finance_Data!G12,Finance_Data!H12) -> CMP_009_East_UK_Foundation_Wholesale_44939_44980
A13: CMP_044 | B13: North | C13: India | D13: Luxury Bag | E13: Wholesale | F13: AUD | G13: 44939 | H13: 44962 | I13: 46433.9 | J13: 0.5441 | K13: 25264.68 | L13: 721451 | M13: 20788 | N13: 240631.87 | O13: 2023 | P13: January | Q13: Q1 | R13: UK | JKL | MNO | PQR | S13: =H13-G13+1 -> 24 | T13: =_xlfn.TEXTJOIN("_",TRUE,Finance_Data!A13,Finance_Data!B13,Finance_Data!C13,Finance_Data!D13,Finance_Data!E13,Finance_Data!G13,Finance_Data!H13) -> CMP_044_North_India_Luxury Bag_Wholesale_44939_44962
... A1001: CMP_008 | B1001: South | C1001: India | D1001: Skincare | E1001: Ecommerce | F1001: USD | G1001: 45827 | H1001: 45875 | I1001: 19852.45 | J1001: 1.0622 | K1001: 21087.27 | L1001: 872752 | M1001: 7466 | N1001: 125496.04 | O1001: 2025 | P1001: June | Q1001: Q2 | R1001: USA | DEF | GHI | S1001: =H1001-G1001+1 -> 49 | T1001: =_xlfn.TEXTJOIN("_",TRUE,Finance_Data!A1001,Finance_Data!B1001,Finance_Data!C1001,Finance_Data!D1001,Finance_Data!E1001,Finance_Data!G1001,Finance_Data!H1001) -> CMP_008_South_India_Skincare_Ecommerce_45827_45875

Sheet Data_Validation
D1: DATA SUMMARY
B2: Total Records | C2: =COUNTA(A6:A1005) -> 1000 | D2: Valid Records | E2: =COUNTIF(N6:N1005,"Pass") -> 983 | F2: Null Records | G2: =COUNTIF(C6:C1005,C6="Missing") -> 0
B3: Duplicate Records | C3: =COUNTIF(D6:D1005,D6="Duplicate") -> 0 | D3: Invalid Records | E3: =C2-E2 -> 17 | F3: Quality % | G3: =E2/C2 -> 0.983
A5: Campaign_ID | B5: Campaign_ID Validation | C5: Null Check for all records | D5: Duplicate Check | E5: Date_Flag | F5: Duration_Flag | G5: FX_Flag | H5: Impression_Flag | I5: Click_Flag | J5: Spend_Flag | K5: Sales_Flag | L5: Month_Flag | M5: Quarter_Flag | N5: Overall_Status
A6: CMP_059 | B6: =IF(ISBLANK(Table3[[#This Row],[Campaign_ID]]),"Invalid","Valid") -> Valid | C6: =IF(COUNTA(Finance_Data!A2:R2)=18,"Valid","Missing") -> Valid | D6: =IF(COUNTIF(Finance_Data!$T$2:$T$1001,Finance_Data!T2)>1,"Duplicate","Valid") -> Valid | E6: =IF(Finance_Data!H2>Finance_Data!G2,"Valid","Invalid") -> Valid | F6: {=_xlfn.IFS(Finance_Data!S2<7,"Short",Finance_Data!S2<=30,"Normal",Finance_Data!S2<=60,"Long",Finance_Data!S2>60,"Very Long")} -> Normal | G6: =IF(ABS(Finance_Data!I2*Finance_Data!J2)-Finance_Data!K2<1,"Valid","Invalid") -> Valid | H6: =IF(Finance_Data!L2>0,"Valid","Invalid") -> Valid | I6: =IF(Finance_Data!L2>=Finance_Data!M2,"Valid","Invalid") -> Valid | J6: =IF(AND(Finance_Data!I2>=0,Finance_Data!K2>=0),"Valid","Invalid") -> Valid | K6: =IF(Finance_Data!N2>=0,"Valid","Invalid") -> Valid | L6: =IF(TEXT(Finance_Data!G2,"mmmm")=Finance_Data!P2,"Valid","Invalid") -> Valid | M6: =IF("Q"&ROUNDUP(MONTH(Finance_Data!G2)/3,0)=Finance_Data!Q2,"Valid","Invalid") -> Valid | N6: =IF(AND(B6="Valid",E6="Valid",G6="Valid",H6="Valid",I6="Valid",J6="Valid",K6="Valid",L6="Valid",M6="Valid"),"Pass","Fail") -> Pass
A7: CMP_001 | B7: =IF(ISBLANK(Table3[[#This Row],[Campaign_ID]]),"Invalid","Valid") -> Valid | C7: =IF(COUNTA(Finance_Data!A3:R3)=18,"Valid","Missing") -> Valid | D7: =IF(COUNTIF(Finance_Data!$T$2:$T$1001,Finance_Data!T3)>1,"Duplicate","Valid") -> Valid | E7: =IF(Finance_Data!H3>Finance_Data!G3,"Valid","Invalid") -> Valid | F7: {=_xlfn.IFS(Finance_Data!S3<7,"Short",Finance_Data!S3<=30,"Normal",Finance_Data!S3<=60,"Long",Finance_Data!S3>60,"Very Long")} -> Long | G7: =IF(ABS(Finance_Data!I3*Finance_Data!J3)-Finance_Data!K3<1,"Valid","Invalid") -> Valid | H7: =IF(Finance_Data!L3>0,"Valid","Invalid") -> Valid | I7: =IF(Finance_Data!L3>=Finance_Data!M3,"Valid","Invalid") -> Valid | J7: =IF(AND(Finance_Data!I3>=0,Finance_Data!K3>=0),"Valid","Invalid") -> Valid | K7: =IF(Finance_Data!N3>=0,"Valid","Invalid") -> Valid | L7: =IF(TEXT(Finance_Data!G3,"mmmm")=Finance_Data!P3,"Valid","Invalid") -> Valid | M7: =IF("Q"&ROUNDUP(MONTH(Finance_Data!G3)/3,0)=Finance_Data!Q3,"Valid","Invalid") -> Valid | N7: =IF(AND(B7="Valid",E7="Valid",G7="Valid",H7="Valid",I7="Valid",J7="Valid",K7="Valid",L7="Valid",M7="Valid"),"Pass","Fail") -> Pass
A8: CMP_027 | B8: =IF(ISBLANK(Table3[[#This Row],[Campaign_ID]]),"Invalid","Valid") -> Valid | C8: =IF(COUNTA(Finance_Data!A4:R4)=18,"Valid","Missing") -> Valid | D8: =IF(COUNTIF(Finance_Data!$T$2:$T$1001,Finance_Data!T4)>1,"Duplicate","Valid") -> Valid | E8: =IF(Finance_Data!H4>Finance_Data!G4,"Valid","Invalid") -> Valid | F8: {=_xlfn.IFS(Finance_Data!S4<7,"Short",Finance_Data!S4<=30,"Normal",Finance_Data!S4<=60,"Long",Finance_Data!S4>60,"Very Long")} -> Long | G8: =IF(ABS(Finance_Data!I4*Finance_Data!J4)-Finance_Data!K4<1,"Valid","Invalid") -> Valid | H8: =IF(Finance_Data!L4>0,"Valid","Invalid") -> Valid | I8: =IF(Finance_Data!L4>=Finance_Data!M4,"Valid","Invalid") -> Valid | J8: =IF(AND(Finance_Data!I4>=0,Finance_Data!K4>=0),"Valid","Invalid") -> Valid | K8: =IF(Finance_Data!N4>=0,"Valid","Invalid") -> Valid | L8: =IF(TEXT(Finance_Data!G4,"mmmm")=Finance_Data!P4,"Valid","Invalid") -> Valid | M8: =IF("Q"&ROUNDUP(MONTH(Finance_Data!G4)/3,0)=Finance_Data!Q4,"Valid","Invalid") -> Valid | N8: =IF(AND(B8="Valid",E8="Valid",G8="Valid",H8="Valid",I8="Valid",J8="Valid",K8="Valid",L8="Valid",M8="Valid"),"Pass","Fail") -> Pass
A9: CMP_027 | B9: =IF(ISBLANK(Table3[[#This Row],[Campaign_ID]]),"Invalid","Valid") -> Valid | C9: =IF(COUNTA(Finance_Data!A5:R5)=18,"Valid","Missing") -> Valid | D9: =IF(COUNTIF(Finance_Data!$T$2:$T$1001,Finance_Data!T5)>1,"Duplicate","Valid") -> Valid | E9: =IF(Finance_Data!H5>Finance_Data!G5,"Valid","Invalid") -> Valid | F9: {=_xlfn.IFS(Finance_Data!S5<7,"Short",Finance_Data!S5<=30,"Normal",Finance_Data!S5<=60,"Long",Finance_Data!S5>60,"Very Long")} -> Long | G9: =IF(ABS(Finance_Data!I5*Finance_Data!J5)-Finance_Data!K5<1,"Valid","Invalid") -> Valid | H9: =IF(Finance_Data!L5>0,"Valid","Invalid") -> Valid | I9: =IF(Finance_Data!L5>=Finance_Data!M5,"Valid","Invalid") -> Valid | J9: =IF(AND(Finance_Data!I5>=0,Finance_Data!K5>=0),"Valid","Invalid") -> Valid | K9: =IF(Finance_Data!N5>=0,"Valid","Invalid") -> Valid | L9: =IF(TEXT(Finance_Data!G5,"mmmm")=Finance_Data!P5,"Valid","Invalid") -> Valid | M9: =IF("Q"&ROUNDUP(MONTH(Finance_Data!G5)/3,0)=Finance_Data!Q5,"Valid","Invalid") -> Valid | N9: =IF(AND(B9="Valid",E9="Valid",G9="Valid",H9="Valid",I9="Valid",J9="Valid",K9="Valid",L9="Valid",M9="Valid"),"Pass","Fail") -> Pass
A10: CMP_009 | B10: =IF(ISBLANK(Table3[[#This Row],[Campaign_ID]]),"Invalid","Valid") -> Valid | C10: =IF(COUNTA(Finance_Data!A6:R6)=18,"Valid","Missing") -> Valid | D10: =IF(COUNTIF(Finance_Data!$T$2:$T$1001,Finance_Data!T6)>1,"Duplicate","Valid") -> Valid | E10: =IF(Finance_Data!H6>Finance_Data!G6,"Valid","Invalid") -> Valid | F10: {=_xlfn.IFS(Finance_Data!S6<7,"Short",Finance_Data!S6<=30,"Normal",Finance_Data!S6<=60,"Long",Finance_Data!S6>60,"Very Long")} -> Normal | G10: =IF(ABS(Finance_Data!I6*Finance_Data!J6)-Finance_Data!K6<1,"Valid","Invalid") -> Valid | H10: =IF(Finance_Data!L6>0,"Valid","Invalid") -> Valid | I10: =IF(Finance_Data!L6>=Finance_Data!M6,"Valid","Invalid") -> Valid | J10: =IF(AND(Finance_Data!I6>=0,Finance_Data!K6>=0),"Valid","Invalid") -> Valid | K10: =IF(Finance_Data!N6>=0,"Valid","Invalid") -> Valid | L10: =IF(TEXT(Finance_Data!G6,"mmmm")=Finance_Data!P6,"Valid","Invalid") -> Valid | M10: =IF("Q"&ROUNDUP(MONTH(Finance_Data!G6)/3,0)=Finance_Data!Q6,"Valid","Invalid") -> Valid | N10: =IF(AND(B10="Valid",E10="Valid",G10="Valid",H10="Valid",I10="Valid",J10="Valid",K10="Valid",L10="Valid",M10="Valid"),"Pass","Fail") -> Pass
A11: CMP_047 | B11: =IF(ISBLANK(Table3[[#This Row],[Campaign_ID]]),"Invalid","Valid") -> Valid | C11: =IF(COUNTA(Finance_Data!A7:R7)=18,"Valid","Missing") -> Valid | D11: =IF(COUNTIF(Finance_Data!$T$2:$T$1001,Finance_Data!T7)>1,"Duplicate","Valid") -> Valid | E11: =IF(Finance_Data!H7>Finance_Data!G7,"Valid","Invalid") -> Valid | F11: {=_xlfn.IFS(Finance_Data!S7<7,"Short",Finance_Data!S7<=30,"Normal",Finance_Data!S7<=60,"Long",Finance_Data!S7>60,"Very Long")} -> Long | G11: =IF(ABS(Finance_Data!I7*Finance_Data!J7)-Finance_Data!K7<1,"Valid","Invalid") -> Valid | H11: =IF(Finance_Data!L7>0,"Valid","Invalid") -> Valid | I11: =IF(Finance_Data!L7>=Finance_Data!M7,"Valid","Invalid") -> Valid | J11: =IF(AND(Finance_Data!I7>=0,Finance_Data!K7>=0),"Valid","Invalid") -> Valid | K11: =IF(Finance_Data!N7>=0,"Valid","Invalid") -> Valid | L11: =IF(TEXT(Finance_Data!G7,"mmmm")=Finance_Data!P7,"Valid","Invalid") -> Valid | M11: =IF("Q"&ROUNDUP(MONTH(Finance_Data!G7)/3,0)=Finance_Data!Q7,"Valid","Invalid") -> Valid | N11: =IF(AND(B11="Valid",E11="Valid",G11="Valid",H11="Valid",I11="Valid",J11="Valid",K11="Valid",L11="Valid",M11="Valid"),"Pass","Fail") -> Pass
A12: CMP_054 | B12: =IF(ISBLANK(Table3[[#This Row],[Campaign_ID]]),"Invalid","Valid") -> Valid | C12: =IF(COUNTA(Finance_Data!A8:R8)=18,"Valid","Missing") -> Valid | D12: =IF(COUNTIF(Finance_Data!$T$2:$T$1001,Finance_Data!T8)>1,"Duplicate","Valid") -> Valid | E12: =IF(Finance_Data!H8>Finance_Data!G8,"Valid","Invalid") -> Valid | F12: {=_xlfn.IFS(Finance_Data!S8<7,"Short",Finance_Data!S8<=30,"Normal",Finance_Data!S8<=60,"Long",Finance_Data!S8>60,"Very Long")} -> Normal | G12: =IF(ABS(Finance_Data!I8*Finance_Data!J8)-Finance_Data!K8<1,"Valid","Invalid") -> Valid | H12: =IF(Finance_Data!L8>0,"Valid","Invalid") -> Valid | I12: =IF(Finance_Data!L8>=Finance_Data!M8,"Valid","Invalid") -> Valid | J12: =IF(AND(Finance_Data!I8>=0,Finance_Data!K8>=0),"Valid","Invalid") -> Valid | K12: =IF(Finance_Data!N8>=0,"Valid","Invalid") -> Valid | L12: =IF(TEXT(Finance_Data!G8,"mmmm")=Finance_Data!P8,"Valid","Invalid") -> Valid | M12: =IF("Q"&ROUNDUP(MONTH(Finance_Data!G8)/3,0)=Finance_Data!Q8,"Valid","Invalid") -> Valid | N12: =IF(AND(B12="Valid",E12="Valid",G12="Valid",H12="Valid",I12="Valid",J12="Valid",K12="Valid",L12="Valid",M12="Valid"),"Pass","Fail") -> Pass
A13: CMP_040 | B13: =IF(ISBLANK(Table3[[#This Row],[Campaign_ID]]),"Invalid","Valid") -> Valid | C13: =IF(COUNTA(Finance_Data!A9:R9)=18,"Valid","Missing") -> Valid | D13: =IF(COUNTIF(Finance_Data!$T$2:$T$1001,Finance_Data!T9)>1,"Duplicate","Valid") -> Valid | E13: =IF(Finance_Data!H9>Finance_Data!G9,"Valid","Invalid") -> Valid | F13: {=_xlfn.IFS(Finance_Data!S9<7,"Short",Finance_Data!S9<=30,"Normal",Finance_Data!S9<=60,"Long",Finance_Data!S9>60,"Very Long")} -> Long | G13: =IF(ABS(Finance_Data!I9*Finance_Data!J9)-Finance_Data!K9<1,"Valid","Invalid") -> Valid | H13: =IF(Finance_Data!L9>0,"Valid","Invalid") -> Valid | I13: =IF(Finance_Data!L9>=Finance_Data!M9,"Valid","Invalid") -> Valid | J13: =IF(AND(Finance_Data!I9>=0,Finance_Data!K9>=0),"Valid","Invalid") -> Valid | K13: =IF(Finance_Data!N9>=0,"Valid","Invalid") -> Valid | L13: =IF(TEXT(Finance_Data!G9,"mmmm")=Finance_Data!P9,"Valid","Invalid") -> Valid | M13: =IF("Q"&ROUNDUP(MONTH(Finance_Data!G9)/3,0)=Finance_Data!Q9,"Valid","Invalid") -> Valid | N13: =IF(AND(B13="Valid",E13="Valid",G13="Valid",H13="Valid",I13="Valid",J13="Valid",K13="Valid",L13="Valid",M13="Valid"),"Pass","Fail") -> Pass
A14: CMP_006 | B14: =IF(ISBLANK(Table3[[#This Row],[Campaign_ID]]),"Invalid","Valid") -> Valid | C14: =IF(COUNTA(Finance_Data!A10:R10)=18,"Valid","Missing") -> Valid | D14: =IF(COUNTIF(Finance_Data!$T$2:$T$1001,Finance_Data!T10)>1,"Duplicate","Valid") -> Valid | E14: =IF(Finance_Data!H10>Finance_Data!G10,"Valid","Invalid") -> Valid | F14: {=_xlfn.IFS(Finance_Data!S10<7,"Short",Finance_Data!S10<=30,"Normal",Finance_Data!S10<=60,"Long",Finance_Data!S10>60,"Very Long")} -> Normal | G14: =IF(ABS(Finance_Data!I10*Finance_Data!J10)-Finance_Data!K10<1,"Valid","Invalid") -> Valid | H14: =IF(Finance_Data!L10>0,"Valid","Invalid") -> Valid | I14: =IF(Finance_Data!L10>=Finance_Data!M10,"Valid","Invalid") -> Valid | J14: =IF(AND(Finance_Data!I10>=0,Finance_Data!K10>=0),"Valid","Invalid") -> Valid | K14: =IF(Finance_Data!N10>=0,"Valid","Invalid") -> Valid | L14: =IF(TEXT(Finance_Data!G10,"mmmm")=Finance_Data!P10,"Valid","Invalid") -> Valid | M14: =IF("Q"&ROUNDUP(MONTH(Finance_Data!G10)/3,0)=Finance_Data!Q10,"Valid","Invalid") -> Valid | N14: =IF(AND(B14="Valid",E14="Valid",G14="Valid",H14="Valid",I14="Valid",J14="Valid",K14="Valid",L14="Valid",M14="Valid"),"Pass","Fail") -> Pass
A15: CMP_003 | B15: =IF(ISBLANK(Table3[[#This Row],[Campaign_ID]]),"Invalid","Valid") -> Valid | C15: =IF(COUNTA(Finance_Data!A11:R11)=18,"Valid","Missing") -> Valid | D15: =IF(COUNTIF(Finance_Data!$T$2:$T$1001,Finance_Data!T11)>1,"Duplicate","Valid") -> Valid | E15: =IF(Finance_Data!H11>Finance_Data!G11,"Valid","Invalid") -> Valid | F15: {=_xlfn.IFS(Finance_Data!S11<7,"Short",Finance_Data!S11<=30,"Normal",Finance_Data!S11<=60,"Long",Finance_Data!S11>60,"Very Long")} -> Normal | G15: =IF(ABS(Finance_Data!I11*Finance_Data!J11)-Finance_Data!K11<1,"Valid","Invalid") -> Valid | H15: =IF(Finance_Data!L11>0,"Valid","Invalid") -> Valid | I15: =IF(Finance_Data!L11>=Finance_Data!M11,"Valid","Invalid") -> Valid | J15: =IF(AND(Finance_Data!I11>=0,Finance_Data!K11>=0),"Valid","Invalid") -> Valid | K15: =IF(Finance_Data!N11>=0,"Valid","Invalid") -> Valid | L15: =IF(TEXT(Finance_Data!G11,"mmmm")=Finance_Data!P11,"Valid","Invalid") -> Valid | M15: =IF("Q"&ROUNDUP(MONTH(Finance_Data!G11)/3,0)=Finance_Data!Q11,"Valid","Invalid") -> Valid | N15: =IF(AND(B15="Valid",E15="Valid",G15="Valid",H15="Valid",I15="Valid",J15="Valid",K15="Valid",L15="Valid",M15="Valid"),"Pass","Fail") -> Pass
A16: CMP_009 | B16: =IF(ISBLANK(Table3[[#This Row],[Campaign_ID]]),"Invalid","Valid") -> Valid | C16: =IF(COUNTA(Finance_Data!A12:R12)=18,"Valid","Missing") -> Valid | D16: =IF(COUNTIF(Finance_Data!$T$2:$T$1001,Finance_Data!T12)>1,"Duplicate","Valid") -> Valid | E16: =IF(Finance_Data!H12>Finance_Data!G12,"Valid","Invalid") -> Valid | F16: {=_xlfn.IFS(Finance_Data!S12<7,"Short",Finance_Data!S12<=30,"Normal",Finance_Data!S12<=60,"Long",Finance_Data!S12>60,"Very Long")} -> Long | G16: =IF(ABS(Finance_Data!I12*Finance_Data!J12)-Finance_Data!K12<1,"Valid","Invalid") -> Valid | H16: =IF(Finance_Data!L12>0,"Valid","Invalid") -> Valid | I16: =IF(Finance_Data!L12>=Finance_Data!M12,"Valid","Invalid") -> Valid | J16: =IF(AND(Finance_Data!I12>=0,Finance_Data!K12>=0),"Valid","Invalid") -> Valid | K16: =IF(Finance_Data!N12>=0,"Valid","Invalid") -> Valid | L16: =IF(TEXT(Finance_Data!G12,"mmmm")=Finance_Data!P12,"Valid","Invalid") -> Valid | M16: =IF("Q"&ROUNDUP(MONTH(Finance_Data!G12)/3,0)=Finance_Data!Q12,"Valid","Invalid") -> Valid | N16: =IF(AND(B16="Valid",E16="Valid",G16="Valid",H16="Valid",I16="Valid",J16="Valid",K16="Valid",L16="Valid",M16="Valid"),"Pass","Fail") -> Pass
A17: CMP_044 | B17: =IF(ISBLANK(Table3[[#This Row],[Campaign_ID]]),"Invalid","Valid") -> Valid | C17: =IF(COUNTA(Finance_Data!A13:R13)=18,"Valid","Missing") -> Valid | D17: =IF(COUNTIF(Finance_Data!$T$2:$T$1001,Finance_Data!T13)>1,"Duplicate","Valid") -> Valid | E17: =IF(Finance_Data!H13>Finance_Data!G13,"Valid","Invalid") -> Valid | F17: {=_xlfn.IFS(Finance_Data!S13<7,"Short",Finance_Data!S13<=30,"Normal",Finance_Data!S13<=60,"Long",Finance_Data!S13>60,"Very Long")} -> Normal | G17: =IF(ABS(Finance_Data!I13*Finance_Data!J13)-Finance_Data!K13<1,"Valid","Invalid") -> Valid | H17: =IF(Finance_Data!L13>0,"Valid","Invalid") -> Valid | I17: =IF(Finance_Data!L13>=Finance_Data!M13,"Valid","Invalid") -> Valid | J17: =IF(AND(Finance_Data!I13>=0,Finance_Data!K13>=0),"Valid","Invalid") -> Valid | K17: =IF(Finance_Data!N13>=0,"Valid","Invalid") -> Valid | L17: =IF(TEXT(Finance_Data!G13,"mmmm")=Finance_Data!P13,"Valid","Invalid") -> Valid | M17: =IF("Q"&ROUNDUP(MONTH(Finance_Data!G13)/3,0)=Finance_Data!Q13,"Valid","Invalid") -> Valid | N17: =IF(AND(B17="Valid",E17="Valid",G17="Valid",H17="Valid",I17="Valid",J17="Valid",K17="Valid",L17="Valid",M17="Valid"),"Pass","Fail") -> Pass
... A1005: CMP_008 | B1005: =IF(ISBLANK(Table3[[#This Row],[Campaign_ID]]),"Invalid","Valid") -> Valid | C1005: =IF(COUNTA(Finance_Data!A1001:R1001)=18,"Valid","Missing") -> Valid | D1005: =IF(COUNTIF(Finance_Data!$T$2:$T$1001,Finance_Data!T1001)>1,"Duplicate","Valid") -> Valid | E1005: =IF(Finance_Data!H1001>Finance_Data!G1001,"Valid","Invalid") -> Valid | F1005: {=_xlfn.IFS(Finance_Data!S1001<7,"Short",Finance_Data!S1001<=30,"Normal",Finance_Data!S1001<=60,"Long",Finance_Data!S1001>60,"Very Long")} -> Long | G1005: =IF(ABS(Finance_Data!I1001*Finance_Data!J1001)-Finance_Data!K1001<1,"Valid","Invalid") -> Valid | H1005: =IF(Finance_Data!L1001>0,"Valid","Invalid") -> Valid | I1005: =IF(Finance_Data!L1001>=Finance_Data!M1001,"Valid","Invalid") -> Valid | J1005: =IF(AND(Finance_Data!I1001>=0,Finance_Data!K1001>=0),"Valid","Invalid") -> Valid | K1005: =IF(Finance_Data!N1001>=0,"Valid","Invalid") -> Valid | L1005: =IF(TEXT(Finance_Data!G1001,"mmmm")=Finance_Data!P1001,"Valid","Invalid") -> Valid | M1005: =IF("Q"&ROUNDUP(MONTH(Finance_Data!G1001)/3,0)=Finance_Data!Q1001,"Valid","Invalid") -> Valid | N1005: =IF(AND(B1005="Valid",E1005="Valid",G1005="Valid",H1005="Valid",I1005="Valid",J1005="Valid",K1005="Valid",L1005="Valid",M1005="Valid"),"Pass","Fail") -> Pass

Sheet KPI_Calculation
E1: KPI SUMMARY
A2: Volume Metrics | B2: Total Campaigns | C2: =COUNTA(_xlfn.UNIQUE(Table2[Campaign_ID])) -> 60 | D2: Total Impressions | E2: =SUM(Table2[Impressions]) -> 508045081 | F2: Total Clicks | G2: =SUM(Table2[Clicks]) -> 25220387 | H2: Total Sales | I2: =SUM(Table2[Sales]) -> 1.2456007e+08 | J2: Total Spend | K2: =SUM(Table2[USD_Spend]) -> 15870820
A3: Performance Metrics | B3: Overall CTR | C3: =G2/E2 -> 0.049642026 | D3: Overall CPC | E3: =K2/G2 -> 0.62928537 | F3: Overall CPM | G3: =K2/E2*1000 -> 31.239 | H3: Overall ROAS | I3: =I2/K2 -> 7.8483697 | J3: Overall ROI | K3: =(I2-K2)/K2 -> 6.8483697
A4: Campaign Metrics | B4: Avg Campaign Duration | C4: =AVERAGE(Table2[Duration]) -> 33.825 | D4: Longest Campaign | E4: =MAX(Table2[Duration]) -> 61 | F4: Shortest Campaign | G4: =MIN(Table2[Duration]) -> 6
A5: Efficiency Metrics | B5: Best Campaign ROAS | C5: =MAX(Table2[ROAS]) -> 1603.5389 | D5: Worst Campaign ROAS | E5: =MIN(Table2[ROAS]) -> 0.11245928 | F5: Highest Sales | G5: =MAX(Table2[Sales]) -> 249994.27 | H5: Lowest Sales | I5: =MIN(Table2[Sales]) -> 5020.96 | J5: Highest Spend | K5: =MAX(Table2[USD_Spend]) -> 58427.41 | L5: Lowest Sales | M5: =MIN(Table2[USD_Spend]) -> 53.48
A7: Campaign_ID | B7: Region | C7: Country | D7: Product | E7: Channel | F7: USD_Spend | G7: Impressions | H7: Clicks | I7: Sales | J7: Duration | K7: CTR | L7: CPC | M7: CPM | N7: ROAS | O7: ROI | P7: Year | Q7: Month | R7: Quarter | S7: Month-Year | T7: Revenue per Click | U7: Revenue per Impression | V7: Daily Spend | W7: Daily Revenue | X7: Daily Clicks | Y7: Daily Impressions | Z7: Engagement Score | AA7: Overall Status
A8: CMP_059 | B8: East | C8: India | D8: Perfume | E8: Retail | F8: 11480.43 | G8: 146828 | H8: 22431 | I8: 180649.72 | J8: 27 | K8: =H8/G8 -> 0.15277059 | L8: =F8/H8 -> 0.51181089 | M8: =F8/G8*1000 -> 78.18965 | N8: =I8/F8 -> 15.735449 | O8: =(I8-F8)/F8 -> 14.735449 | P8: 2023 | Q8: January | R8: Q1 | S8: =DATE(Table2[[#This Row],[Year]],MONTH(DATEVALUE("1-"&Table2[[#This Row],[Month]]&"-2000")),1) -> 44927 | T8: =I8/H8 -> 8.0535741 | U8: =I8/G8 -> 1.2303493 | V8: =F8/J8 -> 425.20111 | W8: =I8/J8 -> 6690.7304 | X8: =H8/J8 -> 830.77778 | Y8: =G8/J8 -> 5438.0741 | Z8: {=_xlfn.IFS(K8<2%,"Low",K8<5%,"Medium",K8<10%,"Good",K8>10%,"Excellent")} -> Excellent | AA8: =Data_Validation!N6 -> Pass
A9: CMP_001 | B9: North | C9: UK | D9: Skincare | E9: Wholesale | F9: 23696.65 | G9: 313300 | H9: 42898 | I9: 243160.04 | J9: 58 | K9: =H9/G9 -> 0.13692308 | L9: =F9/H9 -> 0.55239522 | M9: =F9/G9*1000 -> 75.635653 | N9: =I9/F9 -> 10.261368 | O9: =(I9-F9)/F9 -> 9.2613677 | P9: 2023 | Q9: January | R9: Q1 | S9: =DATE(Table2[[#This Row],[Year]],MONTH(DATEVALUE("1-"&Table2[[#This Row],[Month]]&"-2000")),1) -> 44927 | T9: =I9/H9 -> 5.6683305 | U9: =I9/G9 -> 0.77612525 | V9: =F9/J9 -> 408.56293 | W9: =I9/J9 -> 4192.4145 | X9: =H9/J9 -> 739.62069 | Y9: =G9/J9 -> 5401.7241 | Z9: {=_xlfn.IFS(K9<2%,"Low",K9<5%,"Medium",K9<10%,"Good",K9>10%,"Excellent")} -> Excellent | AA9: =Data_Validation!N7 -> Pass
A10: CMP_027 | B10: East | C10: India | D10: Watch | E10: Wholesale | F10: 36694.84 | G10: 64382 | H10: 21268 | I10: 110974.3 | J10: 33 | K10: =H10/G10 -> 0.33034078 | L10: =F10/H10 -> 1.7253545 | M10: =F10/G10*1000 -> 569.95496 | N10: =I10/F10 -> 3.0242481 | O10: =(I10-F10)/F10 -> 2.0242481 | P10: 2023 | Q10: January | R10: Q1 | S10: =DATE(Table2[[#This Row],[Year]],MONTH(DATEVALUE("1-"&Table2[[#This Row],[Month]]&"-2000")),1) -> 44927 | T10: =I10/H10 -> 5.2179001 | U10: =I10/G10 -> 1.7236852 | V10: =F10/J10 -> 1111.9648 | W10: =I10/J10 -> 3362.8576 | X10: =H10/J10 -> 644.48485 | Y10: =G10/J10 -> 1950.9697 | Z10: {=_xlfn.IFS(K10<2%,"Low",K10<5%,"Medium",K10<10%,"Good",K10>10%,"Excellent")} -> Excellent | AA10: =Data_Validation!N8 -> Pass
A11: CMP_027 | B11: East | C11: Singapore | D11: Foundation | E11: Wholesale | F11: 2894.08 | G11: 228677 | H11: 46629 | I11: 48638.18 | J11: 33 | K11: =H11/G11 -> 0.2039077 | L11: =F11/H11 -> 0.062066096 | M11: =F11/G11*1000 -> 12.655755 | N11: =I11/F11 -> 16.806094 | O11: =(I11-F11)/F11 -> 15.806094 | P11: 2023 | Q11: January | R11: Q1 | S11: =DATE(Table2[[#This Row],[Year]],MONTH(DATEVALUE("1-"&Table2[[#This Row],[Month]]&"-2000")),1) -> 44927 | T11: =I11/H11 -> 1.0430886 | U11: =I11/G11 -> 0.2126938 | V11: =F11/J11 -> 87.699394 | W11: =I11/J11 -> 1473.8842 | X11: =H11/J11 -> 1413 | Y11: =G11/J11 -> 6929.6061 | Z11: {=_xlfn.IFS(K11<2%,"Low",K11<5%,"Medium",K11<10%,"Good",K11>10%,"Excellent")} -> Excellent | AA11: =Data_Validation!N9 -> Pass
A12: CMP_009 | B12: West | C12: UK | D12: Watch | E12: Ecommerce | F12: 37828.13 | G12: 126041 | H12: 12523 | I12: 74800.44 | J12: 28 | K12: =H12/G12 -> 0.099356559 | L12: =F12/H12 -> 3.0206923 | M12: =F12/G12*1000 -> 300.12559 | N12: =I12/F12 -> 1.9773761 | O12: =(I12-F12)/F12 -> 0.9773761 | P12: 2023 | Q12: January | R12: Q1 | S12: =DATE(Table2[[#This Row],[Year]],MONTH(DATEVALUE("1-"&Table2[[#This Row],[Month]]&"-2000")),1) -> 44927 | T12: =I12/H12 -> 5.9730448 | U12: =I12/G12 -> 0.59346118 | V12: =F12/J12 -> 1351.0046 | W12: =I12/J12 -> 2671.4443 | X12: =H12/J12 -> 447.25 | Y12: =G12/J12 -> 4501.4643 | Z12: {=_xlfn.IFS(K12<2%,"Low",K12<5%,"Medium",K12<10%,"Good",K12>10%,"Excellent")} -> Good | AA12: =Data_Validation!N10 -> Pass
A13: CMP_047 | B13: South | C13: UK | D13: Skincare | E13: Retail | F13: 8598.43 | G13: 122369 | H13: 437 | I13: 90681.82 | J13: 45 | K13: =H13/G13 -> 0.0035711659 | L13: =F13/H13 -> 19.676041 | M13: =F13/G13*1000 -> 70.266407 | N13: =I13/F13 -> 10.546323 | O13: =(I13-F13)/F13 -> 9.546323 | P13: 2023 | Q13: January | R13: Q1 | S13: =DATE(Table2[[#This Row],[Year]],MONTH(DATEVALUE("1-"&Table2[[#This Row],[Month]]&"-2000")),1) -> 44927 | T13: =I13/H13 -> 207.50989 | U13: =I13/G13 -> 0.74105223 | V13: =F13/J13 -> 191.07622 | W13: =I13/J13 -> 2015.1516 | X13: =H13/J13 -> 9.7111111 | Y13: =G13/J13 -> 2719.3111 | Z13: {=_xlfn.IFS(K13<2%,"Low",K13<5%,"Medium",K13<10%,"Good",K13>10%,"Excellent")} -> Low | AA13: =Data_Validation!N11 -> Pass
A14: CMP_054 | B14: West | C14: Australia | D14: Perfume | E14: Ecommerce | F14: 24147.15 | G14: 290608 | H14: 43267 | I14: 69802.27 | J14: 29 | K14: =H14/G14 -> 0.14888441 | L14: =F14/H14 -> 0.55809624 | M14: =F14/G14*1000 -> 83.091828 | N14: =I14/F14 -> 2.8907043 | O14: =(I14-F14)/F14 -> 1.8907043 | P14: 2023 | Q14: January | R14: Q1 | S14: =DATE(Table2[[#This Row],[Year]],MONTH(DATEVALUE("1-"&Table2[[#This Row],[Month]]&"-2000")),1) -> 44927 | T14: =I14/H14 -> 1.6132912 | U14: =I14/G14 -> 0.2401939 | V14: =F14/J14 -> 832.66034 | W14: =I14/J14 -> 2406.9748 | X14: =H14/J14 -> 1491.9655 | Y14: =G14/J14 -> 10020.966 | Z14: {=_xlfn.IFS(K14<2%,"Low",K14<5%,"Medium",K14<10%,"Good",K14>10%,"Excellent")} -> Excellent | AA14: =Data_Validation!N12 -> Pass
A15: CMP_040 | B15: East | C15: India | D15: Skincare | E15: Ecommerce | F15: 6070.99 | G15: 354625 | H15: 23530 | I15: 224159.27 | J15: 60 | K15: =H15/G15 -> 0.06635178 | L15: =F15/H15 -> 0.25801062 | M15: =F15/G15*1000 -> 17.119464 | N15: =I15/F15 -> 36.923017 | O15: =(I15-F15)/F15 -> 35.923017 | P15: 2023 | Q15: January | R15: Q1 | S15: =DATE(Table2[[#This Row],[Year]],MONTH(DATEVALUE("1-"&Table2[[#This Row],[Month]]&"-2000")),1) -> 44927 | T15: =I15/H15 -> 9.5265308 | U15: =I15/G15 -> 0.63210228 | V15: =F15/J15 -> 101.18317 | W15: =I15/J15 -> 3735.9878 | X15: =H15/J15 -> 392.16667 | Y15: =G15/J15 -> 5910.4167 | Z15: {=_xlfn.IFS(K15<2%,"Low",K15<5%,"Medium",K15<10%,"Good",K15>10%,"Excellent")} -> Good | AA15: =Data_Validation!N13 -> Pass
A16: CMP_006 | B16: East | C16: Australia | D16: Lipstick | E16: Ecommerce | F16: 34140.35 | G16: 723612 | H16: 46577 | I16: 92666.15 | J16: 20 | K16: =H16/G16 -> 0.064367368 | L16: =F16/H16 -> 0.73298731 | M16: =F16/G16*1000 -> 47.180464 | N16: =I16/F16 -> 2.7142707 | O16: =(I16-F16)/F16 -> 1.7142707 | P16: 2023 | Q16: January | R16: Q1 | S16: =DATE(Table2[[#This Row],[Year]],MONTH(DATEVALUE("1-"&Table2[[#This Row],[Month]]&"-2000")),1) -> 44927 | T16: =I16/H16 -> 1.9895259 | U16: =I16/G16 -> 0.12806055 | V16: =F16/J16 -> 1707.0175 | W16: =I16/J16 -> 4633.3075 | X16: =H16/J16 -> 2328.85 | Y16: =G16/J16 -> 36180.6 | Z16: {=_xlfn.IFS(K16<2%,"Low",K16<5%,"Medium",K16<10%,"Good",K16>10%,"Excellent")} -> Good | AA16: =Data_Validation!N14 -> Pass
A17: CMP_003 | B17: North | C17: Australia | D17: Luxury Bag | E17: Retail | F17: 16097.33 | G17: 707640 | H17: 38271 | I17: 198355.76 | J17: 9 | K17: =H17/G17 -> 0.054082584 | L17: =F17/H17 -> 0.4206143 | M17: =F17/G17*1000 -> 22.747909 | N17: =I17/F17 -> 12.322277 | O17: =(I17-F17)/F17 -> 11.322277 | P17: 2023 | Q17: January | R17: Q1 | S17: =DATE(Table2[[#This Row],[Year]],MONTH(DATEVALUE("1-"&Table2[[#This Row],[Month]]&"-2000")),1) -> 44927 | T17: =I17/H17 -> 5.182926 | U17: =I17/G17 -> 0.28030603 | V17: =F17/J17 -> 1788.5922 | W17: =I17/J17 -> 22039.529 | X17: =H17/J17 -> 4252.3333 | Y17: =G17/J17 -> 78626.667 | Z17: {=_xlfn.IFS(K17<2%,"Low",K17<5%,"Medium",K17<10%,"Good",K17>10%,"Excellent")} -> Good | AA17: =Data_Validation!N15 -> Pass
A18: CMP_009 | B18: East | C18: UK | D18: Foundation | E18: Wholesale | F18: 21094.81 | G18: 812598 | H18: 12055 | I18: 120092.36 | J18: 42 | K18: =H18/G18 -> 0.014835134 | L18: =F18/H18 -> 1.7498805 | M18: =F18/G18*1000 -> 25.959712 | N18: =I18/F18 -> 5.6929814 | O18: =(I18-F18)/F18 -> 4.6929814 | P18: 2023 | Q18: January | R18: Q1 | S18: =DATE(Table2[[#This Row],[Year]],MONTH(DATEVALUE("1-"&Table2[[#This Row],[Month]]&"-2000")),1) -> 44927 | T18: =I18/H18 -> 9.9620373 | U18: =I18/G18 -> 0.14778816 | V18: =F18/J18 -> 502.25738 | W18: =I18/J18 -> 2859.3419 | X18: =H18/J18 -> 287.02381 | Y18: =G18/J18 -> 19347.571 | Z18: {=_xlfn.IFS(K18<2%,"Low",K18<5%,"Medium",K18<10%,"Good",K18>10%,"Excellent")} -> Low | AA18: =Data_Validation!N16 -> Pass
A19: CMP_044 | B19: North | C19: India | D19: Luxury Bag | E19: Wholesale | F19: 25264.68 | G19: 721451 | H19: 20788 | I19: 240631.87 | J19: 24 | K19: =H19/G19 -> 0.028814154 | L19: =F19/H19 -> 1.2153492 | M19: =F19/G19*1000 -> 35.01926 | N19: =I19/F19 -> 9.5244377 | O19: =(I19-F19)/F19 -> 8.5244377 | P19: 2023 | Q19: January | R19: Q1 | S19: =DATE(Table2[[#This Row],[Year]],MONTH(DATEVALUE("1-"&Table2[[#This Row],[Month]]&"-2000")),1) -> 44927 | T19: =I19/H19 -> 11.575518 | U19: =I19/G19 -> 0.33353876 | V19: =F19/J19 -> 1052.695 | W19: =I19/J19 -> 10026.328 | X19: =H19/J19 -> 866.16667 | Y19: =G19/J19 -> 30060.458 | Z19: {=_xlfn.IFS(K19<2%,"Low",K19<5%,"Medium",K19<10%,"Good",K19>10%,"Excellent")} -> Medium | AA19: =Data_Validation!N17 -> Pass
... A1007: CMP_008 | B1007: South | C1007: India | D1007: Skincare | E1007: Ecommerce | F1007: 21087.27 | G1007: 872752 | H1007: 7466 | I1007: 125496.04 | J1007: 49 | K1007: =H1007/G1007 -> 0.0085545493 | L1007: =F1007/H1007 -> 2.8244401 | M1007: =F1007/G1007*1000 -> 24.161812 | N1007: =I1007/F1007 -> 5.9512701 | O1007: =(I1007-F1007)/F1007 -> 4.9512701 | P1007: 2025 | Q1007: June | R1007: Q2 | S1007: =DATE(Table2[[#This Row],[Year]],MONTH(DATEVALUE("1-"&Table2[[#This Row],[Month]]&"-2000")),1) -> 45809 | T1007: =I1007/H1007 -> 16.809006 | U1007: =I1007/G1007 -> 0.14379347 | V1007: =F1007/J1007 -> 430.35245 | W1007: =I1007/J1007 -> 2561.1437 | X1007: =H1007/J1007 -> 152.36735 | Y1007: =G1007/J1007 -> 17811.265 | Z1007: {=_xlfn.IFS(K1007<2%,"Low",K1007<5%,"Medium",K1007<10%,"Good",K1007>10%,"Excellent")} -> Low | AA1007: =Data_Validation!N1005 -> Pass

Sheet Outlier_Detection
A1: THRESHOLD TABLE | D1: OUTLIER SUMMARY
A2: Spend Threshold (95%) | B2: =_xlfn.PERCENTILE.INC(F10:F1009,0.95) -> 42287.894 | D2: No. of High Spend Records | E2: =COUNTIF(Table4[High Spend Flag],"High Spend") -> 50 | F2: No. of High Revenue Records | G2: =COUNTIF(Table4[High Revenue Flag],"High Revenue") -> 50
A3: Revenue Threshold (95%) | B3: =_xlfn.PERCENTILE.INC(Table4[Sales],0.95) -> 232793.51 | D3: No. of High CTR Records | E3: =COUNTIF(Table4[High CTR Flag],"High CTR") -> 50 | F3: No of Poor ROAS Records | G3: =COUNTIF(Table4[ROAS Band],"Poor") -> 45
A4: CTR Threshold (95%) | B4: =_xlfn.PERCENTILE.INC(Table4[CTR],0.95) -> 0.3963346 | D4: No of Records with Wasted Budget | E4: =COUNTIF(Table4[Spend Efficiency Flag],"Wasted Budget") -> 180 | F4: No of Records with Poor Monitization | G4: =COUNTIF(Table4[Click vs Sales Monitization Flag],"Poor Monetization") -> 54
A5: Spend Threshold (75%) | B5: =_xlfn.PERCENTILE.INC(Table4[USD_Spend],0.25) -> 4601.8175
A6: Revenue Threshold (25%) | B6: =_xlfn.PERCENTILE.INC(Table4[Sales],0.25) -> 69253.508
A7: Click Threshold (75%) | B7: =_xlfn.PERCENTILE.INC(Table4[Clicks],0.75) -> 38377
A9: Campaign_ID | B9: Region | C9: Country | D9: Product | E9: Channel | F9: USD_Spend | G9: Impressions | H9: Clicks | I9: Sales | J9: Duration | K9: CTR | L9: ROAS | M9: ROI | N9: Revenue per Click | O9: High Spend Flag | P9: High Revenue Flag | Q9: High CTR Flag | R9: ROAS Band | S9: Spend Efficiency Flag | T9: Click vs Sales Monitization Flag
A10: CMP_059 | B10: East | C10: India | D10: Perfume | E10: Retail | F10: 11480.43 | G10: 146828 | H10: 22431 | I10: 180649.72 | J10: 27 | K10: =H10/G10 -> 0.15277059 | L10: =I10/F10 -> 15.735449 | M10: =(I10-F10)/F10 -> 14.735449 | N10: =I10/H10 -> 8.0535741 | O10: =IF(F10<=$B$2,"Normal","High Spend") -> Normal | P10: =IF(Table4[[#This Row],[Sales]]<=$B$3,"Normal","High Revenue") -> Normal | Q10: =IF(Table4[[#This Row],[CTR]]<=$B$4,"Normal","High CTR") -> Normal | R10: =IF(Table4[[#This Row],[ROAS]]<1,"Poor",IF(Table4[[#This Row],[ROAS]]<3,"Average",IF(Table4[[#This Row],[ROAS]]<5,"Good", "Excellent"))) -> Excellent | S10: =IF(AND(Table4[[#This Row],[USD_Spend]]>=$B$5,Table4[[#This Row],[Sales]]<=$B$6),"Wasted Budget","Spend Justified") -> Spend Justified | T10: =IF(AND(Table4[[#This Row],[Clicks]]>=$B$7,Table4[[#This Row],[Sales]]<=$B$6),"Poor Monetization","Normal Monitization") -> Normal Monitization
A11: CMP_001 | B11: North | C11: UK | D11: Skincare | E11: Wholesale | F11: 23696.65 | G11: 313300 | H11: 42898 | I11: 243160.04 | J11: 58 | K11: =H11/G11 -> 0.13692308 | L11: =I11/F11 -> 10.261368 | M11: =(I11-F11)/F11 -> 9.2613677 | N11: =I11/H11 -> 5.6683305 | O11: =IF(F11<=$B$2,"Normal","High Spend") -> Normal | P11: =IF(Table4[[#This Row],[Sales]]<=$B$3,"Normal","High Revenue") -> High Revenue | Q11: =IF(Table4[[#This Row],[CTR]]<=$B$4,"Normal","High CTR") -> Normal | R11: =IF(Table4[[#This Row],[ROAS]]<1,"Poor",IF(Table4[[#This Row],[ROAS]]<3,"Average",IF(Table4[[#This Row],[ROAS]]<5,"Good", "Excellent"))) -> Excellent | S11: =IF(AND(Table4[[#This Row],[USD_Spend]]>=$B$5,Table4[[#This Row],[Sales]]<=$B$6),"Wasted Budget","Spend Justified") -> Spend Justified | T11: =IF(AND(Table4[[#This Row],[Clicks]]>=$B$7,Table4[[#This Row],[Sales]]<=$B$6),"Poor Monetization","Normal Monitization") -> Normal Monitization
A12: CMP_027 | B12: East | C12: India | D12: Watch | E12: Wholesale | F12: 36694.84 | G12: 64382 | H12: 21268 | I12: 110974.3 | J12: 33 | K12: =H12/G12 -> 0.33034078 | L12: =I12/F12 -> 3.0242481 | M12: =(I12-F12)/F12 -> 2.0242481 | N12: =I12/H12 -> 5.2179001 | O12: =IF(F12<=$B$2,"Normal","High Spend") -> Normal | P12: =IF(Table4[[#This Row],[Sales]]<=$B$3,"Normal","High Revenue") -> Normal | Q12: =IF(Table4[[#This Row],[CTR]]<=$B$4,"Normal","High CTR") -> Normal | R12: =IF(Table4[[#This Row],[ROAS]]<1,"Poor",IF(Table4[[#This Row],[ROAS]]<3,"Average",IF(Table4[[#This Row],[ROAS]]<5,"Good", "Excellent"))) -> Good | S12: =IF(AND(Table4[[#This Row],[USD_Spend]]>=$B$5,Table4[[#This Row],[Sales]]<=$B$6),"Wasted Budget","Spend Justified") -> Spend Justified | T12: =IF(AND(Table4[[#This Row],[Clicks]]>=$B$7,Table4[[#This Row],[Sales]]<=$B$6),"Poor Monetization","Normal Monitization") -> Normal Monitization
A13: CMP_027 | B13: East | C13: Singapore | D13: Foundation | E13: Wholesale | F13: 2894.08 | G13: 228677 | H13: 46629 | I13: 48638.18 | J13: 33 | K13: =H13/G13 -> 0.2039077 | L13: =I13/F13 -> 16.806094 | M13: =(I13-F13)/F13 -> 15.806094 | N13: =I13/H13 -> 1.0430886 | O13: =IF(F13<=$B$2,"Normal","High Spend") -> Normal | P13: =IF(Table4[[#This Row],[Sales]]<=$B$3,"Normal","High Revenue") -> Normal | Q13: =IF(Table4[[#This Row],[CTR]]<=$B$4,"Normal","High CTR") -> Normal | R13: =IF(Table4[[#This Row],[ROAS]]<1,"Poor",IF(Table4[[#This Row],[ROAS]]<3,"Average",IF(Table4[[#This Row],[ROAS]]<5,"Good", "Excellent"))) -> Excellent | S13: =IF(AND(Table4[[#This Row],[USD_Spend]]>=$B$5,Table4[[#This Row],[Sales]]<=$B$6),"Wasted Budget","Spend Justified") -> Spend Justified | T13: =IF(AND(Table4[[#This Row],[Clicks]]>=$B$7,Table4[[#This Row],[Sales]]<=$B$6),"Poor Monetization","Normal Monitization") -> Poor Monetization
A14: CMP_009 | B14: West | C14: UK | D14: Watch | E14: Ecommerce | F14: 37828.13 | G14: 126041 | H14: 12523 | I14: 74800.44 | J14: 28 | K14: =H14/G14 -> 0.099356559 | L14: =I14/F14 -> 1.9773761 | M14: =(I14-F14)/F14 -> 0.9773761 | N14: =I14/H14 -> 5.9730448 | O14: =IF(F14<=$B$2,"Normal","High Spend") -> Normal | P14: =IF(Table4[[#This Row],[Sales]]<=$B$3,"Normal","High Revenue") -> Normal | Q14: =IF(Table4[[#This Row],[CTR]]<=$B$4,"Normal","High CTR") -> Normal | R14: =IF(Table4[[#This Row],[ROAS]]<1,"Poor",IF(Table4[[#This Row],[ROAS]]<3,"Average",IF(Table4[[#This Row],[ROAS]]<5,"Good", "Excellent"))) -> Average | S14: =IF(AND(Table4[[#This Row],[USD_Spend]]>=$B$5,Table4[[#This Row],[Sales]]<=$B$6),"Wasted Budget","Spend Justified") -> Spend Justified | T14: =IF(AND(Table4[[#This Row],[Clicks]]>=$B$7,Table4[[#This Row],[Sales]]<=$B$6),"Poor Monetization","Normal Monitization") -> Normal Monitization
A15: CMP_047 | B15: South | C15: UK | D15: Skincare | E15: Retail | F15: 8598.43 | G15: 122369 | H15: 437 | I15: 90681.82 | J15: 45 | K15: =H15/G15 -> 0.0035711659 | L15: =I15/F15 -> 10.546323 | M15: =(I15-F15)/F15 -> 9.546323 | N15: =I15/H15 -> 207.50989 | O15: =IF(F15<=$B$2,"Normal","High Spend") -> Normal | P15: =IF(Table4[[#This Row],[Sales]]<=$B$3,"Normal","High Revenue") -> Normal | Q15: =IF(Table4[[#This Row],[CTR]]<=$B$4,"Normal","High CTR") -> Normal | R15: =IF(Table4[[#This Row],[ROAS]]<1,"Poor",IF(Table4[[#This Row],[ROAS]]<3,"Average",IF(Table4[[#This Row],[ROAS]]<5,"Good", "Excellent"))) -> Excellent | S15: =IF(AND(Table4[[#This Row],[USD_Spend]]>=$B$5,Table4[[#This Row],[Sales]]<=$B$6),"Wasted Budget","Spend Justified") -> Spend Justified | T15: =IF(AND(Table4[[#This Row],[Clicks]]>=$B$7,Table4[[#This Row],[Sales]]<=$B$6),"Poor Monetization","Normal Monitization") -> Normal Monitization
A16: CMP_054 | B16: West | C16: Australia | D16: Perfume | E16: Ecommerce | F16: 24147.15 | G16: 290608 | H16: 43267 | I16: 69802.27 | J16: 29 | K16: =H16/G16 -> 0.14888441 | L16: =I16/F16 -> 2.8907043 | M16: =(I16-F16)/F16 -> 1.8907043 | N16: =I16/H16 -> 1.6132912 | O16: =IF(F16<=$B$2,"Normal","High Spend") -> Normal | P16: =IF(Table4[[#This Row],[Sales]]<=$B$3,"Normal","High Revenue") -> Normal | Q16: =IF(Table4[[#This Row],[CTR]]<=$B$4,"Normal","High CTR") -> Normal | R16: =IF(Table4[[#This Row],[ROAS]]<1,"Poor",IF(Table4[[#This Row],[ROAS]]<3,"Average",IF(Table4[[#This Row],[ROAS]]<5,"Good", "Excellent"))) -> Average | S16: =IF(AND(Table4[[#This Row],[USD_Spend]]>=$B$5,Table4[[#This Row],[Sales]]<=$B$6),"Wasted Budget","Spend Justified") -> Spend Justified | T16: =IF(AND(Table4[[#This Row],[Clicks]]>=$B$7,Table4[[#This Row],[Sales]]<=$B$6),"Poor Monetization","Normal Monitization") -> Normal Monitization
A17: CMP_040 | B17: East | C17: India | D17: Skincare | E17: Ecommerce | F17: 6070.99 | G17: 354625 | H17: 23530 | I17: 224159.27 | J17: 60 | K17: =H17/G17 -> 0.06635178 | L17: =I17/F17 -> 36.923017 | M17: =(I17-F17)/F17 -> 35.923017 | N17: =I17/H17 -> 9.5265308 | O17: =IF(F17<=$B$2,"Normal","High Spend") -> Normal | P17: =IF(Table4[[#This Row],[Sales]]<=$B$3,"Normal","High Revenue") -> Normal | Q17: =IF(Table4[[#This Row],[CTR]]<=$B$4,"Normal","High CTR") -> Normal | R17: =IF(Table4[[#This Row],[ROAS]]<1,"Poor",IF(Table4[[#This Row],[ROAS]]<3,"Average",IF(Table4[[#This Row],[ROAS]]<5,"Good", "Excellent"))) -> Excellent | S17: =IF(AND(Table4[[#This Row],[USD_Spend]]>=$B$5,Table4[[#This Row],[Sales]]<=$B$6),"Wasted Budget","Spend Justified") -> Spend Justified | T17: =IF(AND(Table4[[#This Row],[Clicks]]>=$B$7,Table4[[#This Row],[Sales]]<=$B$6),"Poor Monetization","Normal Monitization") -> Normal Monitization
A18: CMP_006 | B18: East | C18: Australia | D18: Lipstick | E18: Ecommerce | F18: 34140.35 | G18: 723612 | H18: 46577 | I18: 92666.15 | J18: 20 | K18: =H18/G18 -> 0.064367368 | L18: =I18/F18 -> 2.7142707 | M18: =(I18-F18)/F18 -> 1.7142707 | N18: =I18/H18 -> 1.9895259 | O18: =IF(F18<=$B$2,"Normal","High Spend") -> Normal | P18: =IF(Table4[[#This Row],[Sales]]<=$B$3,"Normal","High Revenue") -> Normal | Q18: =IF(Table4[[#This Row],[CTR]]<=$B$4,"Normal","High CTR") -> Normal | R18: =IF(Table4[[#This Row],[ROAS]]<1,"Poor",IF(Table4[[#This Row],[ROAS]]<3,"Average",IF(Table4[[#This Row],[ROAS]]<5,"Good", "Excellent"))) -> Average | S18: =IF(AND(Table4[[#This Row],[USD_Spend]]>=$B$5,Table4[[#This Row],[Sales]]<=$B$6),"Wasted Budget","Spend Justified") -> Spend Justified | T18: =IF(AND(Table4[[#This Row],[Clicks]]>=$B$7,Table4[[#This Row],[Sales]]<=$B$6),"Poor Monetization","Normal Monitization") -> Normal Monitization
A19: CMP_003 | B19: North | C19: Australia | D19: Luxury Bag | E19: Retail | F19: 16097.33 | G19: 707640 | H19: 38271 | I19: 198355.76 | J19: 9 | K19: =H19/G19 -> 0.054082584 | L19: =I19/F19 -> 12.322277 | M19: =(I19-F19)/F19 -> 11.322277 | N19: =I19/H19 -> 5.182926 | O19: =IF(F19<=$B$2,"Normal","High Spend") -> Normal | P19: =IF(Table4[[#This Row],[Sales]]<=$B$3,"Normal","High Revenue") -> Normal | Q19: =IF(Table4[[#This Row],[CTR]]<=$B$4,"Normal","High CTR") -> Normal | R19: =IF(Table4[[#This Row],[ROAS]]<1,"Poor",IF(Table4[[#This Row],[ROAS]]<3,"Average",IF(Table4[[#This Row],[ROAS]]<5,"Good", "Excellent"))) -> Excellent | S19: =IF(AND(Table4[[#This Row],[USD_Spend]]>=$B$5,Table4[[#This Row],[Sales]]<=$B$6),"Wasted Budget","Spend Justified") -> Spend Justified | T19: =IF(AND(Table4[[#This Row],[Clicks]]>=$B$7,Table4[[#This Row],[Sales]]<=$B$6),"Poor Monetization","Normal Monitization") -> Normal Monitization
A20: CMP_009 | B20: East | C20: UK | D20: Foundation | E20: Wholesale | F20: 21094.81 | G20: 812598 | H20: 12055 | I20: 120092.36 | J20: 42 | K20: =H20/G20 -> 0.014835134 | L20: =I20/F20 -> 5.6929814 | M20: =(I20-F20)/F20 -> 4.6929814 | N20: =I20/H20 -> 9.9620373 | O20: =IF(F20<=$B$2,"Normal","High Spend") -> Normal | P20: =IF(Table4[[#This Row],[Sales]]<=$B$3,"Normal","High Revenue") -> Normal | Q20: =IF(Table4[[#This Row],[CTR]]<=$B$4,"Normal","High CTR") -> Normal | R20: =IF(Table4[[#This Row],[ROAS]]<1,"Poor",IF(Table4[[#This Row],[ROAS]]<3,"Average",IF(Table4[[#This Row],[ROAS]]<5,"Good", "Excellent"))) -> Excellent | S20: =IF(AND(Table4[[#This Row],[USD_Spend]]>=$B$5,Table4[[#This Row],[Sales]]<=$B$6),"Wasted Budget","Spend Justified") -> Spend Justified | T20: =IF(AND(Table4[[#This Row],[Clicks]]>=$B$7,Table4[[#This Row],[Sales]]<=$B$6),"Poor Monetization","Normal Monitization") -> Normal Monitization
A21: CMP_044 | B21: North | C21: India | D21: Luxury Bag | E21: Wholesale | F21: 25264.68 | G21: 721451 | H21: 20788 | I21: 240631.87 | J21: 24 | K21: =H21/G21 -> 0.028814154 | L21: =I21/F21 -> 9.5244377 | M21: =(I21-F21)/F21 -> 8.5244377 | N21: =I21/H21 -> 11.575518 | O21: =IF(F21<=$B$2,"Normal","High Spend") -> Normal | P21: =IF(Table4[[#This Row],[Sales]]<=$B$3,"Normal","High Revenue") -> High Revenue | Q21: =IF(Table4[[#This Row],[CTR]]<=$B$4,"Normal","High CTR") -> Normal | R21: =IF(Table4[[#This Row],[ROAS]]<1,"Poor",IF(Table4[[#This Row],[ROAS]]<3,"Average",IF(Table4[[#This Row],[ROAS]]<5,"Good", "Excellent"))) -> Excellent | S21: =IF(AND(Table4[[#This Row],[USD_Spend]]>=$B$5,Table4[[#This Row],[Sales]]<=$B$6),"Wasted Budget","Spend Justified") -> Spend Justified | T21: =IF(AND(Table4[[#This Row],[Clicks]]>=$B$7,Table4[[#This Row],[Sales]]<=$B$6),"Poor Monetization","Normal Monitization") -> Normal Monitization
... A1009: CMP_008 | B1009: South | C1009: India | D1009: Skincare | E1009: Ecommerce | F1009: 21087.27 | G1009: 872752 | H1009: 7466 | I1009: 125496.04 | J1009: 49 | K1009: =H1009/G1009 -> 0.0085545493 | L1009: =I1009/F1009 -> 5.9512701 | M1009: =(I1009-F1009)/F1009 -> 4.9512701 | N1009: =I1009/H1009 -> 16.809006 | O1009: =IF(F1009<=$B$2,"Normal","High Spend") -> Normal | P1009: =IF(Table4[[#This Row],[Sales]]<=$B$3,"Normal","High Revenue") -> Normal | Q1009: =IF(Table4[[#This Row],[CTR]]<=$B$4,"Normal","High CTR") -> Normal | R1009: =IF(Table4[[#This Row],[ROAS]]<1,"Poor",IF(Table4[[#This Row],[ROAS]]<3,"Average",IF(Table4[[#This Row],[ROAS]]<5,"Good", "Excellent"))) -> Excellent | S1009: =IF(AND(Table4[[#This Row],[USD_Spend]]>=$B$5,Table4[[#This Row],[Sales]]<=$B$6),"Wasted Budget","Spend Justified") -> Spend Justified | T1009: =IF(AND(Table4[[#This Row],[Clicks]]>=$B$7,Table4[[#This Row],[Sales]]<=$B$6),"Poor Monetization","Normal Monitization") -> Normal Monitization

Sheet Region_Analysis
A1: REGION SUMMARY
A2: Highest Revenue Region | C2: =INDEX(A11:A14,MATCH(MAX(C11:C14),C11:C14,0)) -> South | D2: Lowest Revenue Region | F2: =INDEX(A11:A14,MATCH(MIN(C11:C14),C11:C14,0)) -> North
A3: Highest Spend Region | C3: =INDEX(A11:A14,MATCH(MAX(B11:B14),B11:B14,0)) -> West | D3: Lowest Spend Region | F3: =INDEX(A11:A14,MATCH(MIN(B11:B14),B11:B14,0)) -> East
A4: Highest ROAS Region | C4: =INDEX(A11:A14,MATCH(MAX(G11:G14),G11:G14,0)) -> South | D4: Lowest ROAS Region | F4: =INDEX(A11:A14,MATCH(MIN(G11:G14),G11:G14,0)) -> West
A5: Highest CTR Region | C5: =INDEX(A11:A14,MATCH(MAX(F11:F14),F11:F14,0)) -> North | D5: Lowest CTR Region | F5: =INDEX(A11:A14,MATCH(MIN(F11:F14),F11:F14,0)) -> South
A6: Highest ROI Region | C6: =INDEX(A11:A14,MATCH(MAX(H11:H14),H11:H14,0)) -> South | D6: Lowest ROI Region | F6: =INDEX(A11:A14,MATCH(MIN(H11:H14),H11:H14,0)) -> West
A8: Overall Status | B8: Pass
A10: Region | B10: Total Spend | C10: Total Revenue | D10: Total Impression | E10: Total Clicks | F10: Avg CTR | G10: Avg ROAS | H10: Avg ROI | J10: Region | K10: Total Spend | L10: Total Revenue | N10: Region | O10: =G10 -> Avg ROAS | Q10: Region | R10: =F10 -> Avg CTR
A11: East | B11: 3664772.7 | C11: 30446808 | D11: 123630325 | E11: 5837744 | F11: 0.047219353 | G11: 8.3079662 | H11: 7.3079662 | J11: East | K11: =B11 -> 3664772.7 | L11: =C11 -> 30446808 | N11: East | O11: =G11 -> 8.3079662 | Q11: East | R11: =F11 -> 0.047219353
A12: North | B12: 3786257 | C12: 29146093 | D12: 118291179 | E12: 6107301 | F12: 0.051629386 | G12: 7.6978645 | H12: 6.6978645 | J12: North | K12: =B12 -> 3786257 | L12: =C12 -> 29146093 | N12: North | O12: =G12 -> 7.6978645 | Q12: North | R12: =F12 -> 0.051629386
A13: South | B13: 3762250.8 | C13: 32794278 | D13: 134939680 | E13: 5982033 | F13: 0.044331163 | G13: 8.7166646 | H13: 7.7166646 | J13: South | K13: =B13 -> 3762250.8 | L13: =C13 -> 32794278 | N13: South | O13: =G13 -> 8.7166646 | Q13: South | R13: =F13 -> 0.044331163
A14: West | B14: 4399103.5 | C14: 30317172 | D14: 130777429 | E14: 6686103 | F14: 0.051125818 | G14: 6.8916705 | H14: 5.8916705 | J14: West | K14: =B14 -> 4399103.5 | L14: =C14 -> 30317172 | N14: West | O14: =G14 -> 6.8916705 | Q14: West | R14: =F14 -> 0.051125818
A15: Grand Total | B15: 15612384 | C15: 1.2270435e+08 | D15: 507638613 | E15: 24613181 | F15: 0.048485636 | G15: 7.8594244 | H15: 6.8594244
A27: Insight :
A28: Revenue Leader – South generated the highest revenue ($32.79M), making it the strongest contributor to overall business performance. Highest Investment Region – West received the highest marketing spend ($4.40M), indicating that the largest portion of the budget was allocated to this region. Efficiency Leader – South delivered the highest ROAS (8.72) and ROI (7.72), making it the most efficient and profitable region. Engagement Leader – North achieved the highest CTR (5.16%), indicating the strongest customer engagement among all regions. Revenue vs Efficiency Insight – Although West received the highest budget allocation, South generated higher revenue and stronger returns with lower spend. Underperforming Region – West recorded the lowest ROAS (6.89) and ROI (5.89), while South recorded the lowest CTR (4.43%). Key Business Finding – South demonstrates that strong business performance is driven by efficient conversion of marketing investments into revenue rather than engagement volume alone.
A39: Recommendation :
A40: Increase focus on South, as it delivers the highest revenue, ROAS, and ROI despite not being the highest-spend region. Analyze the strategies used in South and identify best practices that can be replicated across other regions. Review West's campaign portfolio to understand why the highest level of spending is resulting in the lowest return efficiency. Improve conversion performance in North by leveraging its strong customer engagement and converting more of that engagement into revenue. Investigate the drivers behind South's strong profitability and explore opportunities to scale similar product, channel, and campaign combinations in other regions.

Sheet Country_Analysis
A1: COUNTRY SUMMARY
A2: Highest Revenue Country | C2: =INDEX(A11:A15,MATCH(MAX(C11:C15),C11:C15,0)) -> USA | D2: Lowest Revenue Country | F2: =INDEX(A11:A15,MATCH(MIN(C11:C15),C11:C15)) -> Singapore
A3: Highest Spend Country | C3: =INDEX(A11:A15,MATCH(MAX(B11:B15),B11:B15,0)) -> USA | D3: Lowest Spend Country | F3: =INDEX(A11:A15,MATCH(MIN(B11:B15),B11:B15,0)) -> Australia
A4: Highest ROAS Country | C4: =INDEX(A11:A15,MATCH(MAX(G11:G15),G11:G15,0)) -> Australia | D4: Lowest ROAS Country | F4: =INDEX(A11:A15,MATCH(MIN(G11:G15),G11:G15,0)) -> USA
A5: Highest CTR Country | C5: =INDEX(A11:A15,MATCH(MAX(F11:F15),F11:F15,0)) -> India | D5: Lowest CTR Country | F5: =INDEX(A11:A15,MATCH(MIN(F11:F15),F11:F15,0)) -> UK
A6: Highest ROI Country | C6: =INDEX(A11:A15,MATCH(MAX(H11:H15),H11:H15,0)) -> Australia | D6: Lowest ROI Country | F6: =INDEX(A11:A15,MATCH(MIN(H11:H15),H11:H15,0)) -> USA
A8: Overall Status | B8: Pass
A10: Country | B10: Total Spend | C10: Total Revenue | D10: Total Impressions | E10: Total Clicks | F10: Avg CTR | G10: Avg ROAS | H10: Avg ROI | J10: =A10 -> Country | K10: =B10 -> Total Spend | L10: =C10 -> Total Revenue | N10: Country | O10: =G10 -> Avg ROAS | Q10: =A10 -> Country | R10: =F10 -> Avg CTR
A11: Australia | B11: 2780490.2 | C11: 23057948 | D11: 91548994 | E11: 4636510 | F11: 0.050645122 | G11: 8.2927634 | H11: 7.2927634 | J11: =A11 -> Australia | K11: =B11 -> 2780490.2 | L11: =C11 -> 23057948 | N11: Australia | O11: =G11 -> 8.2927634 | Q11: =A11 -> Australia | R11: =F11 -> 0.050645122
A12: India | B12: 3422607 | C12: 26041087 | D12: 106563371 | E12: 5472147 | F12: 0.051351106 | G12: 7.608553 | H12: 6.608553 | J12: =A12 -> India | K12: =B12 -> 3422607 | L12: =C12 -> 26041087 | N12: India | O12: =G12 -> 7.608553 | Q12: =A12 -> India | R12: =F12 -> 0.051351106
A13: Singapore | B13: 2832727.6 | C13: 22545696 | D13: 100403282 | E13: 4797953 | F13: 0.047786814 | G13: 7.9590061 | H13: 6.9590061 | J13: =A13 -> Singapore | K13: =B13 -> 2832727.6 | L13: =C13 -> 22545696 | N13: Singapore | O13: =G13 -> 7.9590061 | Q13: =A13 -> Singapore | R13: =F13 -> 0.047786814
A14: UK | B14: 3060684.9 | C14: 24924022 | D14: 104100165 | E14: 4694056 | F14: 0.045091725 | G14: 8.1432828 | H14: 7.1432828 | J14: =A14 -> UK | K14: =B14 -> 3060684.9 | L14: =C14 -> 24924022 | N14: UK | O14: =G14 -> 8.1432828 | Q14: =A14 -> UK | R14: =F14 -> 0.045091725
A15: USA | B15: 3515874.3 | C15: 26135598 | D15: 105022801 | E15: 5012515 | F15: 0.047727874 | G15: 7.4335986 | H15: 6.4335986 | J15: =A15 -> USA | K15: =B15 -> 3515874.3 | L15: =C15 -> 26135598 | N15: USA | O15: =G15 -> 7.4335986 | Q15: =A15 -> USA | R15: =F15 -> 0.047727874
A16: Grand Total | B16: 15612384 | C16: 1.2270435e+08 | D16: 507638613 | E16: 24613181 | F16: 0.048485636 | G16: 7.8594244 | H16: 6.8594244
A33: Insight :
A34: Revenue Leader – USA generated the highest revenue ($26.13M) and also recorded the highest marketing spend, making it the largest contributor to overall business volume. Highest Investment Country – USA received the highest spending allocation ($3.52M), indicating strong business focus on this market. Efficiency Leader – Australia delivered the highest ROAS (8.29) and ROI (7.29), making it the most efficient country in converting marketing spend into revenue. Engagement Leader – India achieved the highest CTR (5.14%), indicating the strongest customer engagement among all countries. Revenue vs Efficiency Insight – USA drives the highest revenue, but Australia generates stronger returns on every dollar invested, demonstrating the importance of balancing scale and efficiency. Underperforming Markets – USA recorded the lowest ROAS (7.43) and ROI (6.43), while UK showed the lowest CTR (4.51%), highlighting opportunities for performance improvement. Budget Allocation Insight – The country receiving the highest investment (USA) is not the most efficient market, suggesting that higher spending does not always lead to stronger returns.
A47: Recommendation :
A48: Increase focus on Australia, as it delivers the highest ROAS and ROI and represents the most efficient market for marketing investments. Continue leveraging USA as a major revenue-driving market while identifying opportunities to improve return efficiency and profitability. Analyze customer targeting, campaign execution, and market strategies used in Australia and apply successful practices to other markets. Review USA campaigns to understand why high spending is not translating into proportionally higher returns. Improve customer engagement in the UK by reviewing audience targeting, creative strategy, and campaign effectiveness.

Sheet Product_Analysis
A1: PRODUCT SUMMARY
A2: Highest Revenue Product | C2: =INDEX(A11:A16,MATCH(MAX(C11:C16),C11:C16,0)) -> Watch | D2: Lowest Revenue Product | F2: =INDEX(A11:A16,MATCH(MIN(C11:C16),C11:C16,0)) -> Skincare
A3: Highest Spend Product | C3: =INDEX(A11:A16,MATCH(MAX(B11:B16),B11:B16,0)) -> Perfume | D3: Lowest Spend Product | F3: =INDEX(A11:A16,MATCH(MIN(B11:B16),B11:B16,0)) -> Lipstick
A4: Highest ROAS Product | C4: =INDEX(A11:A16,MATCH(MAX(G11:G16),G11:G16,0)) -> Watch | D4: Lowest ROAS Product | F4: =INDEX(A11:A16,MATCH(MIN(G11:G16),G11:G16,0)) -> Luxury Bag
A5: Highest CTR Product | C5: =INDEX(A11:A16,MATCH(MAX(F11:F16),F11:F16,0)) -> Foundation | D5: Lowest CTR Product | F5: =INDEX(A11:A16,MATCH(MIN(F11:F16),F11:F16,0)) -> Skincare
A6: Highest ROI Product | C6: =INDEX(A11:A16,MATCH(MAX(H11:H16),H11:H16,0)) -> Watch | D6: Lowest ROI Product | F6: =INDEX(A11:A16,MATCH(MIN(H11:H16),H11:H16,0)) -> Luxury Bag
A8: Overall Status | B8: Pass
A10: Product | B10: Total Spend | C10: Total Revenue | D10: Total Impressions | E10: Total Clicks | F10: Avg CTR | G10: Avg ROAS | H10: Avg ROI | J10: =A10 -> Product | K10: =B10 -> Total Spend | L10: =C10 -> Total Revenue | N10: Product | O10: =F10 -> Avg CTR | Q10: Product | R10: =G10 -> Avg ROAS
A11: Foundation | B11: 2766328.5 | C11: 21640597 | D11: 81296047 | E11: 4538972 | F11: 0.055832629 | G11: 7.8228588 | H11: 6.8228588 | J11: =A11 -> Foundation | K11: =B11 -> 2766328.5 | L11: =C11 -> 21640597 | N11: Foundation | O11: =F11 -> 0.055832629 | Q11: Foundation | R11: =G11 -> 7.8228588
A12: Lipstick | B12: 2325386.2 | C12: 19880781 | D12: 79151444 | E12: 3892215 | F12: 0.049174277 | G12: 8.5494533 | H12: 7.5494533 | J12: =A12 -> Lipstick | K12: =B12 -> 2325386.2 | L12: =C12 -> 19880781 | N12: Lipstick | O12: =F12 -> 0.049174277 | Q12: Lipstick | R12: =G12 -> 8.5494533
A13: Luxury Bag | B13: 2624111.8 | C13: 19348723 | D13: 78894866 | E13: 3667031 | F13: 0.04647997 | G13: 7.373437 | H13: 6.373437 | J13: =A13 -> Luxury Bag | K13: =B13 -> 2624111.8 | L13: =C13 -> 19348723 | N13: Luxury Bag | O13: =F13 -> 0.04647997 | Q13: Luxury Bag | R13: =G13 -> 7.373437
A14: Perfume | B14: 2906727 | C14: 21457811 | D14: 88759105 | E14: 4403286 | F14: 0.049609401 | G14: 7.3821212 | H14: 6.3821212 | J14: =A14 -> Perfume | K14: =B14 -> 2906727 | L14: =C14 -> 21457811 | N14: Perfume | O14: =F14 -> 0.049609401 | Q14: Perfume | R14: =G14 -> 7.3821212
A15: Skincare | B15: 2442423.1 | C15: 18282482 | D15: 85881061 | E15: 3697524 | F15: 0.043054009 | G15: 7.4853871 | H15: 6.4853871 | J15: =A15 -> Skincare | K15: =B15 -> 2442423.1 | L15: =C15 -> 18282482 | N15: Skincare | O15: =F15 -> 0.043054009 | Q15: Skincare | R15: =G15 -> 7.4853871
A16: Watch | B16: 2547407.3 | C16: 22093956 | D16: 93656090 | E16: 4414153 | F16: 0.047131511 | G16: 8.6731149 | H16: 7.6731149 | J16: =A16 -> Watch | K16: =B16 -> 2547407.3 | L16: =C16 -> 22093956 | N16: Watch | O16: =F16 -> 0.047131511 | Q16: Watch | R16: =G16 -> 8.6731149
A17: Grand Total | B17: 15612384 | C17: 1.2270435e+08 | D17: 507638613 | E17: 24613181 | F17: 0.048485636 | G17: 7.8594244 | H17: 6.8594244
A35: Insight :
